<?xml version='1.0'?>
<sdf version='1.4'>
<model name="amazon_robot">

<static>false</static>

<link name='chassis'>
  <pose>0 0 .05 0 0 0</pose>
  <collision name='collision'>
    <geometry>
      <box>
        <size>.9 .675 .15</size>
      </box>
    </geometry>
  </collision>

  <visual name='visual'>
    <geometry>
      <box>
        <size>.9 .675 .15</size>
      </box>
    </geometry>
  <material>
    <ambient>1 0.5 0 1</ambient>
    <diffuse>1 0.5 0 1</diffuse>
    <specular>0.1 0.1 0.1 1</specular>
    <emissive>0 0 0 0</emissive>
  </material>
  </visual>

  <collision name='caster_collision_front'>
    <pose>0.40 0 -0.05 0 0 0</pose>
    <geometry>
      <sphere>
        <radius>.05</radius>
      </sphere>
    </geometry>

  <surface>
    <friction>
      <ode>
        <mu>0</mu>
        <mu2>0</mu2>
        <slip1>1.0</slip1>
        <slip2>1.0</slip2>
      </ode>
    </friction>
  </surface>
</collision>

<visual name='caster_visual_front'>
  <pose>0.40 0 -0.05 0 0 0</pose>
  <geometry>
    <sphere>
      <radius>.05</radius>
    </sphere>
  </geometry>
</visual>



  <collision name='caster_collision_back'>
    <pose>-0.40 0 -0.05 0 0 0</pose>
    <geometry>
      <sphere>
        <radius>.05</radius>
      </sphere>
    </geometry>

  <surface>
    <friction>
      <ode>
        <mu>0</mu>
        <mu2>0</mu2>
        <slip1>1.0</slip1>
        <slip2>1.0</slip2>
      </ode>
    </friction>
  </surface>
</collision>

<visual name='caster_visual_back'>
  <pose>-0.40 0 -0.05 0 0 0</pose>
  <geometry>
    <sphere>
      <radius>.05</radius>
    </sphere>
  </geometry>
</visual>






</link>
<link name="left_wheel">
<pose>0 0.30 0.05 0 1.5707 1.5707</pose>
<collision name="collision">
  <geometry>
    <cylinder>
      <radius>.1</radius>
      <length>.05</length>
    </cylinder>
  </geometry>
</collision>
<visual name="visual">
  <geometry>
    <cylinder>
      <radius>.1</radius>
      <length>.05</length>
    </cylinder>
  </geometry>
</visual>
</link>

<link name="right_wheel">
<pose>0 -0.30 0.05 0 1.5707 1.5707</pose>
<collision name="collision">
  <geometry>
    <cylinder>
      <radius>.1</radius>
      <length>.05</length>
    </cylinder>
  </geometry>
</collision>
<visual name="visual">
  <geometry>
    <cylinder>
      <radius>.1</radius>
      <length>.05</length>
    </cylinder>
  </geometry>
</visual>
</link>

<!-- 
Lets try to add something on top of chasis that could screw rotate 
-->

<link name="top_screw_lift">
<pose>0 0 0.2 0 0 0</pose>
<collision name="collision">
  <geometry>
    <cylinder>
      <radius>.3375</radius>
      <length>.03</length>
    </cylinder>
  </geometry>
        <surface>
          <friction>
            <ode>
              <mu>0</mu>
              <mu2>0</mu2>
            </ode>
          </friction>
        </surface>

</collision>
<visual name="visual">
  <geometry>
    <cylinder>
      <radius>.3375</radius>
      <length>.03</length>
    </cylinder>
  </geometry>
</visual>
</link>

<joint type="screw" name="top_screw_lift_hinge">
   <pose>0 0 0.2 0 0 0</pose>
  <child>top_screw_lift</child>
  <parent>chassis</parent>
   <axis>
     <xyz>0 0 -1</xyz>
     <limit>
       <upper>150</upper>
       <lower>0</lower>
     </limit>
   </axis>
   <thread_pitch>3141.6</thread_pitch>
</joint>

<!-- 
Screw rotate ends here
-->

<joint type="revolute" name="left_wheel_hinge">
<pose>0 0 -0.03 0 0 0</pose>
<child>left_wheel</child>
<parent>chassis</parent>
<axis>
  <xyz>0 1 0</xyz>
</axis>
</joint>

<joint type="revolute" name="right_wheel_hinge">
<pose>0 0 0.03 0 0 0</pose>
<child>right_wheel</child>
<parent>chassis</parent>
<axis>
  <xyz>0 1 0</xyz>
</axis>
</joint>

</model>
</sdf>
